Signed-off-by: 林博仁(Buo-ren, Lin) <Buo.Ren.Lin@gmail.com>
Hello!
I've been using this library for years now. I've even made a little contribution to it. I'm interested if it's planned to release new versions to PyPi? The last release was back in September 2018 and there've been a lot of good pull requests merged into master since then.
If currently nobody can be responsible for that, I can help and participate.
Please answer these questions before submitting your issue. Thanks!

1. What version of pyTelegramBotAPI are you using?
the last version
2. What OS are you using?
ubuntu
3. What version of python are you using?
3.6.8 64bit

there is some way to run 2 bots at the same time ?
i really have to make that
Please answer these questions before submitting your issue. Thanks!

1. What version of pyTelegramBotAPI are you using? pyTelegramBotAPI==3.6.6

2. What OS are you using? Debian 9

3. What version of python are you using? Python 3.5.3


Starting from Telegram Bot API 4.2 (April 14, 2019, https://core.telegram.org/bots/api#april-14-2019), there is a new field of the Message Object called "forward_sender_name".
pyTelegramBotAPI seems to don't support this yet, because I can see the field inside message.reply_to_message.json.forward_sender_name, but not directly inside the message object.
I am using pyTelegramBotAPI version 3.6.6, using Arch Linux (GNU/LInux) with python version 3.8.0
### What doesn't work?
I try to read the token from a config file. 
```python
#Creates the bot object and imports preferences
config = configparser.ConfigParser()
config.read('authbot.conf')
TOKEN = config['Security']['TOKEN']
bot.telebot.TeleBot(TOKEN)
```
It's return following error:
```
INFO:requests.packages.urllib3.connectionpool:Starting new HTTPS connection (1): api.telegram.org
DEBUG:requests.packages.urllib3.connectionpool:"GET /bot'1004654243:AAHsL1ZsPooeqF7W2G5fVbLelmMRw7uLtzs'/getUpdates?offset=1&timeout=20 HTTP/1.1" 404 55
ERROR:TeleBot:ApiException occurred, args=('A request to the Telegram API was unsuccessful. The server returned HTTP 404 Not Found. Response body:\n[b\'{"ok":false,"error_code":404,"description":"Not Found"}\']',)
Traceback (most recent call last):
  File "/home/yorozuya3/Desktop/authtelegrambot/env/lib/python3.8/site-packages/telebot/util.py", line 59, in run
    task(*args, **kwargs)
  File "/home/yorozuya3/Desktop/authtelegrambot/env/lib/python3.8/site-packages/telebot/__init__.py", line 276, in __retrieve_updates
    updates = self.get_updates(offset=(self.last_update_id + 1), timeout=timeout)
  File "/home/yorozuya3/Desktop/authtelegrambot/env/lib/python3.8/site-packages/telebot/__init__.py", line 246, in get_updates
    json_updates = apihelper.get_updates(self.token, offset, limit, timeout, allowed_updates)
  File "/home/yorozuya3/Desktop/authtelegrambot/env/lib/python3.8/site-packages/telebot/apihelper.py", line 180, in get_updates
    return _make_request(token, method_url, params=payload)
  File "/home/yorozuya3/Desktop/authtelegrambot/env/lib/python3.8/site-packages/telebot/apihelper.py", line 56, in _make_request
    return _check_result(method_name, result)['result']
  File "/home/yorozuya3/Desktop/authtelegrambot/env/lib/python3.8/site-packages/telebot/apihelper.py", line 75, in _check_result
    raise ApiException(msg, method_name, result)
telebot.apihelper.ApiException: A request to the Telegram API was unsuccessful. The server returned HTTP 404 Not Found. Response body:
[b'{"ok":false,"error_code":404,"description":"Not Found"}']

ERROR:TeleBot:A request to the Telegram API was unsuccessful. The server returned HTTP 404 Not Found. Response body:
[b'{"ok":false,"error_code":404,"description":"Not Found"}']

```
### What works?
```python
TOKEN = 'my token'
bot = telebot.TeleBot(TOKEN)
```
If I sending video and photos as album from desktop client, I sent one message. But if I sending with send_media_group(), I got two instead one: video and photos in separate messages.
Please, fix it to "natural" method.

Please answer these questions before submitting your issue. Thanks!

1. I use pyTelegramBotAPI-3.6.6-py3.7.egg-info

2. Windows 7

3. Python 3.7

I have strange error in file util.py when run my code and don't understand what to do with it.

Code:
db = 'rutracker.sqlite'
    conn = sqlite3.connect(db)
    cursor = conn.cursor()
    answer = ''

    if (CATEGORY is not None) and (SUBCATEGORY is not None):
        try:
            cursor.execute(
                "SELECT * FROM torrents WHERE Category=? AND Subcategory=?", (CATEGORY, SUBCATEGORY)
            )
            result = cursor.fetchall()
            print(result)
            for i in result:
                name = list(i)[2]
                link = list(i)[3]
                if QUERY in name.lower():
                    answer += name + '\n' + link + '\n\n'
            bot.send_message(message.from_user.id, answer)
            conn.commit()
        except sqlite3.DatabaseError as err:
            print("Error: ", err)
        finally:
            conn.close()

Error text:
2019-09-30 20:18:31,384 (util.py:65 WorkerThread1) ERROR - TeleBot: "TypeError occurred, args=("'NoneType' object is not callable",)
Traceback (most recent call last):
  File "C:\Users\home\PycharmProjects\torrent_bot\venv\lib\site-packages\telebot\util.py", line 59, in run
    task(*args, **kwargs)
TypeError: 'NoneType' object is not callable
"
2019-09-30 20:18:31,386 (util.py:65 WorkerThread1) ERROR - TeleBot: "TypeError occurred, args=("'NoneType' object is not callable",)
Traceback (most recent call last):
  File "C:\Users\home\PycharmProjects\torrent_bot\venv\lib\site-packages\telebot\util.py", line 59, in run
    task(*args, **kwargs)
TypeError: 'NoneType' object is not callable
"
Traceback (most recent call last):
  File "C:/Users/home/PycharmProjects/torrent_bot/torrent_bot.py", line 5503, in <module>
2019-09-30 20:18:31,422 (util.py:65 WorkerThread2) ERROR - TeleBot: "TypeError occurred, args=("'NoneType' object is not callable",)
Traceback (most recent call last):
  File "C:\Users\home\PycharmProjects\torrent_bot\venv\lib\site-packages\telebot\util.py", line 59, in run
    task(*args, **kwargs)
TypeError: 'NoneType' object is not callable
"
    bot.polling(none_stop=True, interval=0, timeout=20)
  File "C:\Users\home\PycharmProjects\torrent_bot\venv\lib\site-packages\telebot\__init__.py", line 389, in polling
    self.__threaded_polling(none_stop, interval, timeout)
  File "C:\Users\home\PycharmProjects\torrent_bot\venv\lib\site-packages\telebot\__init__.py", line 413, in __threaded_polling
    self.worker_pool.raise_exceptions()
  File "C:\Users\home\PycharmProjects\torrent_bot\venv\lib\site-packages\telebot\util.py", line 108, in raise_exceptions
    six.reraise(self.exc_info[0], self.exc_info[1], self.exc_info[2])
  File "C:\Users\home\PycharmProjects\torrent_bot\venv\lib\site-packages\six.py", line 693, in reraise
    raise value
  File "C:\Users\home\PycharmProjects\torrent_bot\venv\lib\site-packages\telebot\util.py", line 59, in run
    task(*args, **kwargs)
TypeError: 'NoneType' object is not callable

Debug result on photo.
![image](https://user-images.githubusercontent.com/31971067/65900907-b9faf080-e3bf-11e9-9b5c-e81491ec9fd4.png)



pyTelegramBotAPI 3.6.6
OS Ubuntu 16
python 3.6.7

Sometimes i have problem with call forward_message: i am waiting for response infinity time, then i get responce usually with some error (like MESSAGE_ID_INVALID). Can i set timeout limit on this function call? I can run this functuin in new thread, but there is threads limit in os and i dislike this solution. Anyone help me? Thanks!
Please answer these questions before submitting your issue. Thanks!

1. What version of pyTelegramBotAPI are you using?
last

2. What OS are you using?
mac os

3. What version of python are you using?
3.6

When I'm using autocomplete (like results with InlineQueryResultArticle) I don't see event for offset when my list was scrolled to bottom.

Hi. I found a bug. I'm use pyTelegramBotAPI 3.6.6

If call "set_game_score(chat_id, score, inline_message_id='inline_message_id')", then 
![image](https://user-images.githubusercontent.com/22620605/59321467-cce79900-8cda-11e9-8444-ac4dc795b61b.png)