### Operating system
Ubuntu 16.04.6 LTS 64 bit 
### `nbgrader --version`
nbgrader version 0.6.1
### `jupyterhub --version` (if used with JupyterHub)
$ jupyterhub --version
0.9.6
### `jupyter notebook --version` 
$ jupyter notebook --version
6.0.0
### Expected behavior
Autograde for all students should be successfully
### Actual behavior

only one student can't be Autograde, click Autograde have error as follow 

*******Log Output
[INFO] Copying /home/dku-dasc-02/Stats102/submitted/wms16/q3/jupyter.png -> /home/dku-dasc-02/Stats102/autograded/wms16/q3/jupyter.png
[INFO] Copying /home/dku-dasc-02/Stats102/submitted/wms16/q3/timestamp.txt -> /home/dku-dasc-02/Stats102/autograded/wms16/q3/timestamp.txt
[INFO] Creating/updating student with ID 'wms16': {}
[INFO] SubmittedAssignment<q3 for wms16> submitted at 2020-01-12 03:14:55.209492
[INFO] Overwriting files with master versions from the source directory
[INFO] Copying /home/dku-dasc-02/Stats102/source/./q3/jupyter.png -> /home/dku-dasc-02/Stats102/autograded/wms16/q3/jupyter.png
[WARNING] Skipping unknown notebook: /home/dku-dasc-02/Stats102/submitted/wms16/q3/WMS q3.ipynb
[ERROR] No notebooks found, did you forget to run 'nbgrader generate_assignment'?
[ERROR] There was an error processing assignment: /home/dku-dasc-02/Stats102/submitted/wms16/q3
[ERROR] Traceback (most recent call last):
      File "/home/dku-dasc-02/anaconda3/lib/python3.6/site-packages/nbgrader/converters/base.py", line 332, in convert_notebooks
        self.init_assignment(gd['assignment_id'], gd['student_id'])
      File "/home/dku-dasc-02/anaconda3/lib/python3.6/site-packages/nbgrader/converters/autograde.py", line 154, in init_assignment
        raise NbGraderException(msg)
    nbgrader.converters.base.NbGraderException: No notebooks found, did you forget to run 'nbgrader generate_assignment'?
    
[WARNING] Removing failed assignment: /home/dku-dasc-02/Stats102/autograded/wms16/q3
[ERROR] There was an error processing assignment 'q3' for student 'wms16'
[ERROR] Please see the the above traceback for details on the specific errors on the above failures.

**********Traceback

Traceback (most recent call last):
  File "/home/dku-dasc-02/anaconda3/lib/python3.6/site-packages/nbgrader/utils.py", line 514, in capture_log
    app.start()
  File "/home/dku-dasc-02/anaconda3/lib/python3.6/site-packages/nbgrader/converters/base.py", line 74, in start
    self.convert_notebooks()
  File "/home/dku-dasc-02/anaconda3/lib/python3.6/site-packages/nbgrader/converters/base.py", line 413, in convert_notebooks
    raise NbGraderException(msg)
nbgrader.converters.base.NbGraderException: Please see the the above traceback for details on the specific errors on the above failures.

 screen capture as follow





### Operating system
Ubuntu 16.04
### `nbgrader --version`
nbgrader                  0.6.0                    py36_0    conda-forge
### `jupyterhub --version` (if used with JupyterHub)
0.9.6
### `jupyter notebook --version` 
6.0.0

### Expected behavior
instructor can open manage students tab
### Actual behavior
cannot open manage students tab and cannot see submissions on manual grading
### Steps to reproduce the behavior
visit jupyterhub website and click formgrader-->click manage students tab


I did troubleshooting:

1. F12 check develop mode for chrome browser

jquery.min.js:4 GET https://jp04.dukekunshan.edu.cn/user/dku-dasc-02/formgrader/api/students 500

Sorry, the formgrader encountered an error. Please contact the administrator of the formgrader for further assistance.

2. nbgrader quickstart stats102 again and copy source files again.

3. run nbgrader db student list ok

4. run aa.py

*******************aa.py******************************
from nbgrader.api import Gradebook

with Gradebook("sqlite:///gradebook.db") as gb:
    print("Students:")
    print(gb.students)

    print("--")
    print("Student dictionaries (list comp):")
    print([s.to_dict() for s in gb.students])

    print("--")
    print("Student dictionaries (query):")
    print(gb.student_dicts())

****************************************************************************

(base) dku-dasc-02@dku-dasc-02:~/Stats102.bak$ python3 aa.py
Students:
[Student<carol1>, Student<carol2>, Student<xm38>, Student<az123>, Student<ab787>, Student<cg269>, Student<cs586>, Student<dh262>, Student<yl691>, Student<dk264>, Student<dg249>, Student<dn99>, Student<cs582>, Student<hw255>, Student<jl873>, Student<jh677>, Student<lc349>, Student<mw420>, Student<mt325>, Student<rz102>, Student<rj154>, Student<sz172>, Student<tl266>, Student<yr55>, Student<th270>, Student<wq14>, Student<wms16>, Student<xd55>, Student<yl688>, Student<yw411>, Student<yz520>, Student<yz607>, Student<yq74>, Student<yw410>, Student<yl683>, Student<yy276>, Student<yd135>, Student<yl690>, Student<zs100>, Student<zz233>, Student<zw205>, Student<zy120>, Student<yl687>, Student<user>, Student<yw413>]
--
Student dictionaries (list comp):
[{'id': 'carol1', 'first_name': None, 'last_name': None, 'email': None, 'score': 0.0, 'max_score': 49.0, 'lms_user_id': None}, {'id': 'carol2', 'first_name': None, 'last_name': None, 'email': None, 'score': 2.0, 'max_score': 49.0, 'lms_user_id': None}, {'id': 'xm38', 'first_name': None, 'last_name': None, 'email': None, 'score': 0.0, 'max_score': 49.0, 'lms_user_id': None}, {'id': 'az123', 'first_name': 'Zubair', 'last_name': 'Abuzar', 'email': 'az123@duke.edu', 'score': 0.6, 'max_score': 49.0, 'lms_user_id': None}, {'id': 'ab787', 'first_name': 'Babber', 'last_name': 'Aryaman', 'email': 'ab787@duke.edu', 'score': 4.0, 'max_score': 49.0, 'lms_user_id': None}, {'id': 'cg269', 'first_name': 'Ge', 'last_name': 'Chenhao', 'email': 'cg269@duke.edu', 'score': 7.5, 'max_score': 49.0, 'lms_user_id': None}, {'id': 'cs586', 'first_name': 'Sun', 'last_name': 'Chenxi', 'email': 'cs586@duke.edu', 'score': 6.9, 'max_score': 49.0, 'lms_user_id': None}, {'id': 'dh262', 'first_name': 'Huo', 'last_name': 'Da', 'email': 'dh262@duke.edu', 'score': 0.0, 'max_score': 49.0, 'lms_user_id': None}, {'id': 'yl691', 'first_name': 'Lyu', 'last_name': 'Daisy', 'email': 'yl691@duke.edu', 'score': 7.5, 'max_score': 49.0, 'lms_user_id': None}, {'id': 'dk264', 'first_name': 'Kang', 'last_name': 'Danming', 'email': 'dk264@duke.edu', 'score': 5.5, 'max_score': 49.0, 'lms_user_id': None}, {'id': 'dg249', 'first_name': 'Guo', 'last_name': 'Dongyang', 'email': 'dg249@duke.edu', 'score': 2.7, 'max_score': 49.0, 'lms_user_id': None}, {'id': 'dn99', 'first_name': 'Nyamgerel', 'last_name': 'Dulguun', 'email': 'dn99@duke.edu', 'score': 6.6, 'max_score': 49.0, 'lms_user_id': None}, {'id': 'cs582', 'first_name': 'Flores', 'last_name': 'GustavoSalas', 'email': 'cs582@duke.edu', 'score': 7.5, 'max_score': 49.0, 'lms_user_id': None}, {'id': 'hw255', 'first_name': 'Wang', 'last_name': 'Hongruo', 'email': 'hw255@duke.edu', 'score': 7.5, 'max_score': 49.0, 'lms_user_id': None}, {'id': 'jl873', 'first_name': 'Lee', 'last_name': 'Jennifer', 'email': 'jl873@duke.edu', 'score': 7.5, 'max_score': 49.0, 'lms_user_id': None}, {'id': 'jh677', 'first_name': 'Huang', 'last_name': 'Jiayun', 'email': 'jh677@duke.edu', 'score': 7.5, 'max_score': 49.0, 'lms_user_id': None}, {'id': 'lc349', 'first_name': 'Chen', 'last_name': 'Lihui', 'email': 'lc349@duke.edu', 'score': 5.5, 'max_score': 49.0, 'lms_user_id': None}, {'id': 'mw420', 'first_name': 'Wu', 'last_name': 'Muye', 'email': 'mw420@duke.edu', 'score': 1.35, 'max_score': 49.0, 'lms_user_id': None}, {'id': 'mt325', 'first_name': 'Tao', 'last_name': 'Muzi', 'email': 'mt325@duke.edu', 'score': 5.0, 'max_score': 49.0, 'lms_user_id': None}, {'id': 'rz102', 'first_name': 'Zhu', 'last_name': 'Runzhou', 'email': 'rz102@duke.edu', 'score': 7.5, 'max_score': 49.0, 'lms_user_id': None}, {'id': 'rj154', 'first_name': 'Jiang', 'last_name': 'Ruoxian', 'email': 'rj154@duke.edu', 'score': 7.5, 'max_score': 49.0, 'lms_user_id': None}, {'id': 'sz172', 'first_name': 'Zhu', 'last_name': 'Shengyue', 'email': 'sz172@duke.edu', 'score': 7.5, 'max_score': 49.0, 'lms_user_id': None}, {'id': 'tl266', 'first_name': 'Li', 'last_name': 'Tianlai', 'email': 'tl266@duke.edu', 'score': 7.5, 'max_score': 49.0, 'lms_user_id': None}, {'id': 'yr55', 'first_name': 'Ren', 'last_name': 'Tony', 'email': 'yr55@duke.edu', 'score': 5.35, 'max_score': 49.0, 'lms_user_id': None}, {'id': 'th270', 'first_name': 'Huang', 'last_name': 'Tzu-Liang', 'email': 'th270@duke.edu', 'score': 7.5, 'max_score': 49.0, 'lms_user_id': None}, {'id': 'wq14', 'first_name': 'Qi', 'last_name': 'Wenxin', 'email': 'wq14@duke.edu', 'score': 6.5, 'max_score': 49.0, 'lms_user_id': None}, {'id': 'wms16', 'first_name': 'Sachson', 'last_name': 'Will', 'email': 'wms16@duke.edu', 'score': 0.25, 'max_score': 49.0, 'lms_user_id': None}, {'id': 'xd55', 'first_name': 'Du', 'last_name': 'Xiaotong', 'email': 'xd55@duke.edu', 'score': 7.5, 'max_score': 49.0, 'lms_user_id': None}, {'id': 'yl688', 'first_name': 'Li', 'last_name': 'Ye', 'email': 'yl688@duke.edu', 'score': 5.5, 'max_score': 49.0, 'lms_user_id': None}, {'id': 'yw411', 'first_name': 'Wang', 'last_name': 'Yifu', 'email': 'yw411@duke.edu', 'score': 7.5, 'max_score': 49.0, 'lms_user_id': None}, {'id': 'yz520', 'first_name': 'Zhu', 'last_name': 'Yihan', 'email': 'yz520@duke.edu', 'score': 7.5, 'max_score': 49.0, 'lms_user_id': None}, {'id': 'yz607', 'first_name': 'Zhong', 'last_name': 'Yihao', 'email': 'yz607@duke.edu', 'score': 7.5, 'max_score': 49.0, 'lms_user_id': None}, {'id': 'yq74', 'first_name': 'Qin', 'last_name': 'Yiyuan', 'email': 'yq74@duke.edu', 'score': 5.5, 'max_score': 49.0, 'lms_user_id': None}, {'id': 'yw410', 'first_name': 'Wu', 'last_name': 'Yizhen', 'email': 'yw410@duke.edu', 'score': 7.5, 'max_score': 49.0, 'lms_user_id': None}, {'id': 'yl683', 'first_name': 'Lei', 'last_name': 'Yuanzhi', 'email': 'yl683@duke.edu', 'score': 5.75, 'max_score': 49.0, 'lms_user_id': None}, {'id': 'yy276', 'first_name': 'Yang', 'last_name': 'Yuchen', 'email': 'yy276@duke.edu', 'score': 7.5, 'max_score': 49.0, 'lms_user_id': None}, {'id': 'yd135', 'first_name': 'Dong', 'last_name': 'Yufei', 'email': 'yd135@duke.edu', 'score': 6.45, 'max_score': 49.0, 'lms_user_id': None}, {'id': 'yl690', 'first_name': 'Li', 'last_name': 'Yufei', 'email': 'yl690@duke.edu', 'score': 5.5, 'max_score': 49.0, 'lms_user_id': None}, {'id': 'zs100', 'first_name': 'Shao', 'last_name': 'Zedian', 'email': 'zs100@duke.edu', 'score': 7.5, 'max_score': 49.0, 'lms_user_id': None}, {'id': 'zz233', 'first_name': 'Zhou', 'last_name': 'Zhenru', 'email': 'zz233@duke.edu', 'score': 7.5, 'max_score': 49.0, 'lms_user_id': None}, {'id': 'zw205', 'first_name': 'Wei', 'last_name': 'Zihao', 'email': 'zw205@duke.edu', 'score': 7.0, 'max_score': 49.0, 'lms_user_id': None}, {'id': 'zy120', 'first_name': 'Ye', 'last_name': 'Ziying', 'email': 'zy120@duke.edu', 'score': 5.5, 'max_score': 49.0, 'lms_user_id': None}, {'id': 'yl687', 'first_name': 'yubo', 'last_name': 'liu', 'email': 'yl687@duke.edu', 'score': 4.5, 'max_score': 49.0, 'lms_user_id': None}, {'id': 'user', 'first_name': 'user', 'last_name': 'user', 'email': 'user@duke.edu', 'score': 0.0, 'max_score': 49.0, 'lms_user_id': None}, {'id': 'yw413', 'first_name': 'you', 'last_name': 'wu', 'email': 'yw413@duke.edu', 'score': 5.5, 'max_score': 49.0, 'lms_user_id': None}]
--
Student dictionaries (query):
Traceback (most recent call last):
  File "/home/dku-dasc-02/anaconda3/lib/python3.6/site-packages/sqlalchemy/engine/base.py", line 1249, in _execute_context
    cursor, statement, parameters, context
  File "/home/dku-dasc-02/anaconda3/lib/python3.6/site-packages/sqlalchemy/engine/default.py", line 580, in do_execute
    cursor.execute(statement, parameters)
sqlite3.OperationalError: misuse of aggregate: sum()

The above exception was the direct cause of the following exception:

Traceback (most recent call last):
  File "aa.py", line 13, in <module>
    print(gb.student_dicts())
  File "/home/dku-dasc-02/anaconda3/lib/python3.6/site-packages/nbgrader/api.py", line 2954, in student_dicts
    total_score, = self.db.query(func.sum(Assignment.max_score)).one()
  File "/home/dku-dasc-02/anaconda3/lib/python3.6/site-packages/sqlalchemy/orm/query.py", line 3300, in one
    ret = self.one_or_none()
  File "/home/dku-dasc-02/anaconda3/lib/python3.6/site-packages/sqlalchemy/orm/query.py", line 3269, in one_or_none
    ret = list(self)
  File "/home/dku-dasc-02/anaconda3/lib/python3.6/site-packages/sqlalchemy/orm/query.py", line 3342, in __iter__
    return self._execute_and_instances(context)
  File "/home/dku-dasc-02/anaconda3/lib/python3.6/site-packages/sqlalchemy/orm/query.py", line 3367, in _execute_and_instances
    result = conn.execute(querycontext.statement, self._params)
  File "/home/dku-dasc-02/anaconda3/lib/python3.6/site-packages/sqlalchemy/engine/base.py", line 988, in execute
    return meth(self, multiparams, params)
  File "/home/dku-dasc-02/anaconda3/lib/python3.6/site-packages/sqlalchemy/sql/elements.py", line 287, in _execute_on_connection
    return connection._execute_clauseelement(self, multiparams, params)
  File "/home/dku-dasc-02/anaconda3/lib/python3.6/site-packages/sqlalchemy/engine/base.py", line 1107, in _execute_clauseelement
    distilled_params,
  File "/home/dku-dasc-02/anaconda3/lib/python3.6/site-packages/sqlalchemy/engine/base.py", line 1253, in _execute_context
    e, statement, parameters, cursor, context
  File "/home/dku-dasc-02/anaconda3/lib/python3.6/site-packages/sqlalchemy/engine/base.py", line 1473, in _handle_dbapi_exception
    util.raise_from_cause(sqlalchemy_exception, exc_info)
  File "/home/dku-dasc-02/anaconda3/lib/python3.6/site-packages/sqlalchemy/util/compat.py", line 398, in raise_from_cause
    reraise(type(exception), exception, tb=exc_tb, cause=cause)
  File "/home/dku-dasc-02/anaconda3/lib/python3.6/site-packages/sqlalchemy/util/compat.py", line 152, in reraise
    raise value.with_traceback(tb)
  File "/home/dku-dasc-02/anaconda3/lib/python3.6/site-packages/sqlalchemy/engine/base.py", line 1249, in _execute_context
    cursor, statement, parameters, context
  File "/home/dku-dasc-02/anaconda3/lib/python3.6/site-packages/sqlalchemy/engine/default.py", line 580, in do_execute
    cursor.execute(statement, parameters)
sqlalchemy.exc.OperationalError: (sqlite3.OperationalError) misuse of aggregate: sum()
[SQL: SELECT sum((SELECT coalesce(sum(grade_cells.max_score), ?) AS coalesce_1 
FROM notebook, assignment, base_cell JOIN grade_cells ON base_cell.id = grade_cells.id 
WHERE notebook.assignment_id = assignment.id AND base_cell.notebook_id = notebook.id) + (SELECT coalesce(sum(task_cells.max_score), ?) AS coalesce_3 
FROM notebook, assignment, base_cell JOIN task_cells ON base_cell.id = task_cells.id 
WHERE notebook.assignment_id = assignment.id AND base_cell.notebook_id = notebook.id)) AS sum_1]
[parameters: (0.0, 0.0)]
(Background on this error at: http://sqlalche.me/e/e3q8)




### Operating system

MacOS 10.15.2

### `nbgrader --version`

Python version 3.7.4 (default, Aug 13 2019, 15:17:50)
[Clang 4.0.1 (tags/RELEASE_401/final)]
nbgrader version 0.6.1

### `jupyterhub --version` (if used with JupyterHub)

n/a

### `jupyter notebook --version`

6.0.1

### Expected behavior

Invoking `nbgrader release_assignment PS-1 -f` should have the same effect as clicking the "Generate" button next to PS01 on formgrader's Manage Assignments page.

### Actual behavior

The formgrader seems to work just fine. However, the command line method (with or without the `-f` flag fails with an error message and stack trace:

```
(base) ibeatty@Beatty-MacBook-Pro-2018 p351s20 % nbgrader release_assignment PS01 -f --debug
[ReleaseAssignmentApp | DEBUG] Searching ['/Users/ibeatty/nbgrader/p351s20', '/Users/ibeatty/.jupyter', '/Users/ibeatty/anaconda3/etc/jupyter', '/usr/local/etc/jupyter', '/etc/jupyter'] for config files
[ReleaseAssignmentApp | DEBUG] Looking for jupyter_config in /etc/jupyter
[ReleaseAssignmentApp | DEBUG] Looking for jupyter_config in /usr/local/etc/jupyter
[ReleaseAssignmentApp | DEBUG] Looking for jupyter_config in /Users/ibeatty/anaconda3/etc/jupyter
[ReleaseAssignmentApp | DEBUG] Looking for jupyter_config in /Users/ibeatty/.jupyter
[ReleaseAssignmentApp | DEBUG] Looking for jupyter_config in /Users/ibeatty/nbgrader/p351s20
[ReleaseAssignmentApp | DEBUG] Looking for nbgrader_config in /etc/jupyter
[ReleaseAssignmentApp | DEBUG] Looking for nbgrader_config in /usr/local/etc/jupyter
[ReleaseAssignmentApp | DEBUG] Looking for nbgrader_config in /Users/ibeatty/anaconda3/etc/jupyter
[ReleaseAssignmentApp | DEBUG] Looking for nbgrader_config in /Users/ibeatty/.jupyter
[ReleaseAssignmentApp | DEBUG] Looking for nbgrader_config in /Users/ibeatty/nbgrader/p351s20
[ReleaseAssignmentApp | DEBUG] Loaded config file: /Users/ibeatty/nbgrader/p351s20/nbgrader_config.py
[ReleaseAssignmentApp | DEBUG] Looking for nbgrader_config in /Users/ibeatty/nbgrader/p351s20
[ReleaseAssignmentApp | DEBUG] Loaded config file: /Users/ibeatty/nbgrader/p351s20/nbgrader_config.py
[ReleaseAssignmentApp | DEBUG] Using authenticator: NoAuthPlugin
[ReleaseAssignmentApp | WARNING] Creating exchange directory: /srv/nbgrader/exchange
Traceback (most recent call last):
  File "/Users/ibeatty/anaconda3/bin/nbgrader", line 11, in <module>
    sys.exit(main())
  File "/Users/ibeatty/anaconda3/lib/python3.7/site-packages/nbgrader/apps/nbgraderapp.py", line 319, in main
    NbGraderApp.launch_instance()
  File "/Users/ibeatty/anaconda3/lib/python3.7/site-packages/jupyter_core/application.py", line 267, in launch_instance
    return super(JupyterApp, cls).launch_instance(argv=argv, **kwargs)
  File "/Users/ibeatty/anaconda3/lib/python3.7/site-packages/traitlets/config/application.py", line 664, in launch_instance
    app.start()
  File "/Users/ibeatty/anaconda3/lib/python3.7/site-packages/nbgrader/apps/nbgraderapp.py", line 311, in start
    super(NbGraderApp, self).start()
  File "/Users/ibeatty/anaconda3/lib/python3.7/site-packages/nbgrader/apps/baseapp.py", line 347, in start
    super(NbGrader, self).start()
  File "/Users/ibeatty/anaconda3/lib/python3.7/site-packages/jupyter_core/application.py", line 256, in start
    self.subapp.start()
  File "/Users/ibeatty/anaconda3/lib/python3.7/site-packages/nbgrader/apps/releaseassignmentapp.py", line 107, in start
    release.start()
  File "/Users/ibeatty/anaconda3/lib/python3.7/site-packages/nbgrader/exchange/exchange.py", line 158, in start
    self.ensure_root()
  File "/Users/ibeatty/anaconda3/lib/python3.7/site-packages/nbgrader/exchange/release_assignment.py", line 41, in ensure_root
    os.makedirs(self.root)
  File "/Users/ibeatty/anaconda3/lib/python3.7/os.py", line 211, in makedirs
    makedirs(head, exist_ok=exist_ok)
  File "/Users/ibeatty/anaconda3/lib/python3.7/os.py", line 211, in makedirs
    makedirs(head, exist_ok=exist_ok)
  File "/Users/ibeatty/anaconda3/lib/python3.7/os.py", line 221, in makedirs
    mkdir(name, mode)
OSError: [Errno 30] Read-only file system: '/srv'
```

To me, it looks like the command-line version isn't seeing the same configuration information as formgrader, and thinks I'm using an exchange directory.

### Steps to reproduce the behavior

In a course set up for use with LMS assignment distribution (no JupyterHub, no exchange directory, config file in the course root directory, minimal customization), create an an assignment set and populate it with a few notebooks. Do a bunch of releasing via formgrader as you preview the assignment, find errors, fix them, re-release, etc. Then try releasing from the command line (because I ultimately wanted to use the notebook filter so I can invoke different header and footer for some notebooks than others):

`nbgrader release_assignment PS-1 -f`

Boom. Error every time.
Last login: Thu Jan  9 21:36:35 2020 from 10.200.5.112
(base) dku-dasc-02@dku-dasc-02:~$ conda list |grep tornado
tornado                   6.0.3            py36h516909a_0    conda-forge
(base) dku-dasc-02@dku-dasc-02:~$  conda list |grep jupyterhub
jupyterhub                1.0.0                    py36_0  
(base) dku-dasc-02@dku-dasc-02:~$ conda list |grep notebook
notebook                  6.0.1                    py36_0    conda-forge
(base) dku-dasc-02@dku-dasc-02:~$  conda list |grep nbgrader
nbgrader                  0.6.0                    py36_0    conda-forge
(base) dku-dasc-02@dku-dasc-02:~$  conda list |grep sqlalchemy
sqlalchemy                1.3.10           py36h516909a_0    conda-forge
(base) dku-dasc-02@dku-dasc-02:~$ 

(base) dku-dasc-02@dku-dasc-02:~$ nbgrader --version
Python version 3.6.7 | packaged by conda-forge | (default, Jul  2 2019, 02:18:42) 
[GCC 7.3.0]
nbgrader version 0.6.0
(base) dku-dasc-02@dku-dasc-02:~$ 

root@dku-dasc-02:~# jupyterhub --version
1.0.0
ERROR:asyncio:Task exception was never retrieved
future: <Task finished coro=<JupyterHub.launch_instance_async() done, defined at /home/dku-dasc-02/anaconda3/lib/python3.6/site-packages/jupyterhub/app.py:2477> exception=SystemExit(0,)>
Traceback (most recent call last):
  File "/home/dku-dasc-02/anaconda3/lib/python3.6/site-packages/jupyterhub/app.py", line 2492, in launch_instance
    loop.start()
  File "/home/dku-dasc-02/anaconda3/lib/python3.6/site-packages/tornado/platform/asyncio.py", line 148, in start
    self.asyncio_loop.run_forever()
  File "/home/dku-dasc-02/anaconda3/lib/python3.6/asyncio/base_events.py", line 427, in run_forever
    self._run_once()
  File "/home/dku-dasc-02/anaconda3/lib/python3.6/asyncio/base_events.py", line 1440, in _run_once
    handle._run()
  File "/home/dku-dasc-02/anaconda3/lib/python3.6/asyncio/events.py", line 145, in _run
    self._callback(*self._args)
  File "/home/dku-dasc-02/anaconda3/lib/python3.6/site-packages/jupyterhub/app.py", line 2479, in launch_instance_async
    await self.initialize(argv)
  File "/home/dku-dasc-02/anaconda3/lib/python3.6/site-packages/jupyterhub/app.py", line 2085, in initialize
    super().initialize(*args, **kwargs)
  File "</home/dku-dasc-02/anaconda3/lib/python3.6/site-packages/decorator.py:decorator-gen-2>", line 2, in initialize
  File "/home/dku-dasc-02/anaconda3/lib/python3.6/site-packages/traitlets/config/application.py", line 87, in catch_config_error
    return method(app, *args, **kwargs)
  File "/home/dku-dasc-02/anaconda3/lib/python3.6/site-packages/traitlets/config/application.py", line 297, in initialize
    self.parse_command_line(argv)
  File "</home/dku-dasc-02/anaconda3/lib/python3.6/site-packages/decorator.py:decorator-gen-4>", line 2, in parse_command_line
  File "/home/dku-dasc-02/anaconda3/lib/python3.6/site-packages/traitlets/config/application.py", line 87, in catch_config_error
    return method(app, *args, **kwargs)
  File "/home/dku-dasc-02/anaconda3/lib/python3.6/site-packages/traitlets/config/application.py", line 532, in parse_command_line
    self.exit(0)
  File "/home/dku-dasc-02/anaconda3/lib/python3.6/site-packages/traitlets/config/application.py", line 654, in exit
    sys.exit(exit_status)
SystemExit: 0

root@dku-dasc-02:~# jupyter notebook --version
6.0.1
root@dku-dasc-02:~# 



How do I prevent students from adding any import statements in nbGrader cell?
### Operating system
Linux RedHat 7.4

### `nbgrader --version`
0.6.1
### `jupyterhub --version` (if used with JupyterHub)
1.0.0
### `jupyter notebook --version` 
5.5.0

A prof ran into this problem while running nbgrader:
    UnicodeEncodeError: 'charmap' codec can't encode character '\u2080' in position 54: character maps to <undefined>

His Comment:

That is the code for superscript zero. Eliminating that in the notebook,
brought up other messages: superscripts don’t work, → does not, ≤ does
not, but greek letters and ⇒ do work. The same characters in the course
notes (00 …, 01…) work, those notebooks can be generated and released, but
the Lab01 notebook not.

More of his comments:

John, I narrowed down the issue: the error appears only in cells that are marked
as “Read-only” under View → Cell toolbar → Create assignment. Since I don’t
bother with that for the course notes, but do mark cells with the questions are
read-only in assignments and exams, so students always see the original question,
that didn’t appear for the course notes. A temporary solution is not to use
read-only cells.

Any help on this would be appreciated.
<!--
Thanks for helping to improve nbgrader!

If you are submitting a bug report or looking for support, please use the below
template so we can efficiently solve the problem.

If you are requesting a new feature, feel free to remove irrelevant pieces of
the issue template. 
-->


### Operating system

MacOS 10.15.2

### `nbgrader --version`

Python version 3.7.4 (default, Aug 13 2019, 15:17:50)
[Clang 4.0.1 (tags/RELEASE_401/final)]
nbgrader version 0.6.1

### `jupyterhub --version` (if used with JupyterHub)

Not using.

### `jupyter notebook --version` 

6.0.1

### Expected behavior

I just upgraded both my iMac desktop and my MacBook laptop to Catalina (MacOS 10.15.2), and did a fresh download and install of Anaconda, nbgrader, and a bunch of notebook extensions on each. I followed exactly the same protocol for each machine.

I've got a directory containing a nbgrader course, which I created on the laptop (pre-upgrade), pushed up to GitHub, and then pulled down to the desktop. Both copies are fully synced with the repository, and both have the same absolute path on each computer (`/Users/<username>/nbgrader/p351s20`, where the username is the same. the `nbgrader_config.py` file is very simple, unmodified (I believe) from what the quickstart creates.

On each machine, I launched jupyter from the command line after `cd`-ing ito the course directory. I have edited my `~/.jupyter/jupyter_notebook_config.py` file very slightly, setting the default browser to be Chrome -- making the same change on both machines.

On the laptop (where the quickstart was originally run and the course files created), launching jupyter and clicking the Formgrader tab produces the expected "Manage Assignments" page, showing the one problem set that I've already customized somewhat from the quickstart example.

I expect Formgrader to work in the same way on the desktop, allowing me to manage assignments and grade on either computer (so long as I'm good about keeping the two machines synchronized via GitHub pushes).

### Actual behavior

On the desktop, launching jupyter and clicking the Formgrader tab produces a page entitled "Error" that says "Sorry, the formgrader encountered an error. Please contact the administrator of the formgrader for further assistance."

However, from the Files tab of the main Jupyter page, I can drill down into the folder hierarchy and open one of the problem set's notebooks just fine. The "Validate" button appears, and seems to work properly.

### Steps to reproduce the behavior

Described above. (Sorry, but it seemed necessary for the expected and actual behaviors to make sense.)
I've been using nbgrader for the first time this term.  It's beena  very positive experience, but there are several features that I feel would help my workflow.

One of the simplest (from my naive perspective) would be comment hints on the commenting boxes when I'm manually grading. To explain: I find myself repeatedly writing the same things in specific comment boxes (because many students have the same error). Perhaps for next year I can change my tests to catch those specific errors and make a relevant comment. However, since I'm not aware of being able to alter the tests of a released assignment, I need to explain it through comments. At the moment, I have appropriate blocks of text in a text editor, and I have to copy and paste them each time I need them.

If there was the option to have some sort of drop-down list of the comments previously made in that same comment box in other student's work, this would make life so much simpler!


### `nbgrader --version` 0.6.0
### `jupyter notebook --version`  6.0.1

Trying to make nbgrader work with multiple  courses.
when I press "release" button in the formgrader the status of the assignment stays in "draft" and no collect button shows up


### Operating system
Fedora 30 server

### `nbgrader --version`
```
Python version 3.7.3 (default, Mar 27 2019, 13:36:35) 
[GCC 9.0.1 20190227 (Red Hat 9.0.1-0.8)]
nbgrader version 0.6.1
```

### `jupyterhub --version` (if used with JupyterHub)
```
1.0.0
```

### `jupyter notebook --version` 
```
6.0.1
```

### Expected behavior
status changes to "released", "collect" button appears

### Actual behavior
status stays in "draft", no "collect" button appears

### Steps to reproduce the behavior
I have no idea.

Might be related to #863 
https://github.com/jupyter/nbgrader/blob/4c5d6f606c8a2ec7b51e05f7f08797be6252f7f5/nbgrader/server_extensions/course_list/handlers.py#L60

I get empty string a self.token here.
Where the problem might be?

I am following the instructions for many courses